<?xml version="1.0" encoding="utf-8"?><testsuites><testsuite name="pytest" errors="5" failures="0" skipped="0" tests="5" time="4.705" timestamp="2023-02-21T09:58:34.818630" hostname="MacBook Pro: kolfert"><testcase classname="" name="ccvm.ccvmplotlib.tests.test_BoxQP_metadata" time="0.000"><error message="collection failure">ImportError while importing test module '/Users/kolfert/projects/ccvm/ccvm/ccvmplotlib/tests/test_BoxQP_metadata.py'.
Hint: make sure your test modules/packages have valid Python names.
Traceback:
/Library/Frameworks/Python.framework/Versions/3.9/lib/python3.9/importlib/__init__.py:127: in import_module
    return _bootstrap._gcd_import(name[level:], package, level)
ccvmplotlib/__init__.py:1: in &lt;module&gt;
    from .ccvmplotlib import ccvmplotlib
ccvmplotlib/ccvmplotlib.py:8: in &lt;module&gt;
    from ccvm_simulators.ccvmplotlib.problem_metadata import ProblemMetadataFactory
ccvmplotlib/problem_metadata/__init__.py:1: in &lt;module&gt;
    from .boxqp_metadata import BoxQPMetadata
ccvmplotlib/problem_metadata/boxqp_metadata.py:6: in &lt;module&gt;
    from ccvm_simulators.ccvmplotlib.utils.sampleTTSmetric import SampleTTSMetric
ccvmplotlib/utils/sampleTTSmetric.py:6: in &lt;module&gt;
    from .metric import Metric
ccvmplotlib/utils/metric.py:3: in &lt;module&gt;
    from .mixins import StrDictMixIn
ccvmplotlib/utils/mixins.py:2: in &lt;module&gt;
    from future.utils import iteritems
E   ModuleNotFoundError: No module named 'future'</error></testcase><testcase classname="" name="ccvm.ccvmplotlib.tests.test_ccvmplotlib" time="0.000"><error message="collection failure">ImportError while importing test module '/Users/kolfert/projects/ccvm/ccvm/ccvmplotlib/tests/test_ccvmplotlib.py'.
Hint: make sure your test modules/packages have valid Python names.
Traceback:
/Library/Frameworks/Python.framework/Versions/3.9/lib/python3.9/importlib/__init__.py:127: in import_module
    return _bootstrap._gcd_import(name[level:], package, level)
ccvmplotlib/__init__.py:1: in &lt;module&gt;
    from .ccvmplotlib import ccvmplotlib
ccvmplotlib/ccvmplotlib.py:8: in &lt;module&gt;
    from ccvm_simulators.ccvmplotlib.problem_metadata import ProblemMetadataFactory
ccvmplotlib/problem_metadata/__init__.py:1: in &lt;module&gt;
    from .boxqp_metadata import BoxQPMetadata
ccvmplotlib/problem_metadata/boxqp_metadata.py:6: in &lt;module&gt;
    from ccvm_simulators.ccvmplotlib.utils.sampleTTSmetric import SampleTTSMetric
ccvmplotlib/utils/sampleTTSmetric.py:6: in &lt;module&gt;
    from .metric import Metric
ccvmplotlib/utils/metric.py:3: in &lt;module&gt;
    from .mixins import StrDictMixIn
ccvmplotlib/utils/mixins.py:2: in &lt;module&gt;
    from future.utils import iteritems
E   ModuleNotFoundError: No module named 'future'</error></testcase><testcase classname="" name="ccvm.ccvmplotlib.tests.test_problem_metadata" time="0.000"><error message="collection failure">ImportError while importing test module '/Users/kolfert/projects/ccvm/ccvm/ccvmplotlib/tests/test_problem_metadata.py'.
Hint: make sure your test modules/packages have valid Python names.
Traceback:
/Library/Frameworks/Python.framework/Versions/3.9/lib/python3.9/importlib/__init__.py:127: in import_module
    return _bootstrap._gcd_import(name[level:], package, level)
ccvmplotlib/__init__.py:1: in &lt;module&gt;
    from .ccvmplotlib import ccvmplotlib
ccvmplotlib/ccvmplotlib.py:8: in &lt;module&gt;
    from ccvm_simulators.ccvmplotlib.problem_metadata import ProblemMetadataFactory
ccvmplotlib/problem_metadata/__init__.py:1: in &lt;module&gt;
    from .boxqp_metadata import BoxQPMetadata
ccvmplotlib/problem_metadata/boxqp_metadata.py:6: in &lt;module&gt;
    from ccvm_simulators.ccvmplotlib.utils.sampleTTSmetric import SampleTTSMetric
ccvmplotlib/utils/sampleTTSmetric.py:6: in &lt;module&gt;
    from .metric import Metric
ccvmplotlib/utils/metric.py:3: in &lt;module&gt;
    from .mixins import StrDictMixIn
ccvmplotlib/utils/mixins.py:2: in &lt;module&gt;
    from future.utils import iteritems
E   ModuleNotFoundError: No module named 'future'</error></testcase><testcase classname="" name="ccvm.ccvmplotlib.tests.test_problem_metadata_factory" time="0.000"><error message="collection failure">ImportError while importing test module '/Users/kolfert/projects/ccvm/ccvm/ccvmplotlib/tests/test_problem_metadata_factory.py'.
Hint: make sure your test modules/packages have valid Python names.
Traceback:
/Library/Frameworks/Python.framework/Versions/3.9/lib/python3.9/importlib/__init__.py:127: in import_module
    return _bootstrap._gcd_import(name[level:], package, level)
ccvmplotlib/__init__.py:1: in &lt;module&gt;
    from .ccvmplotlib import ccvmplotlib
ccvmplotlib/ccvmplotlib.py:8: in &lt;module&gt;
    from ccvm_simulators.ccvmplotlib.problem_metadata import ProblemMetadataFactory
ccvmplotlib/problem_metadata/__init__.py:1: in &lt;module&gt;
    from .boxqp_metadata import BoxQPMetadata
ccvmplotlib/problem_metadata/boxqp_metadata.py:6: in &lt;module&gt;
    from ccvm_simulators.ccvmplotlib.utils.sampleTTSmetric import SampleTTSMetric
ccvmplotlib/utils/sampleTTSmetric.py:6: in &lt;module&gt;
    from .metric import Metric
ccvmplotlib/utils/metric.py:3: in &lt;module&gt;
    from .mixins import StrDictMixIn
ccvmplotlib/utils/mixins.py:2: in &lt;module&gt;
    from future.utils import iteritems
E   ModuleNotFoundError: No module named 'future'</error></testcase><testcase classname="pytest" name="internal" time="0.000"><error message="internal error">Traceback (most recent call last):
  File "/Users/kolfert/Library/Python/3.9/lib/python/site-packages/_pytest/main.py", line 270, in wrap_session
    session.exitstatus = doit(config, session) or 0
  File "/Users/kolfert/Library/Python/3.9/lib/python/site-packages/_pytest/main.py", line 323, in _main
    config.hook.pytest_collection(session=session)
  File "/Users/kolfert/Library/Python/3.9/lib/python/site-packages/pluggy/hooks.py", line 286, in __call__
    return self._hookexec(self, self.get_hookimpls(), kwargs)
  File "/Users/kolfert/Library/Python/3.9/lib/python/site-packages/pluggy/manager.py", line 93, in _hookexec
    return self._inner_hookexec(hook, methods, kwargs)
  File "/Users/kolfert/Library/Python/3.9/lib/python/site-packages/pluggy/manager.py", line 84, in &lt;lambda&gt;
    self._inner_hookexec = lambda hook, methods, kwargs: hook.multicall(
  File "/Users/kolfert/Library/Python/3.9/lib/python/site-packages/pluggy/callers.py", line 208, in _multicall
    return outcome.get_result()
  File "/Users/kolfert/Library/Python/3.9/lib/python/site-packages/pluggy/callers.py", line 80, in get_result
    raise ex[1].with_traceback(ex[2])
  File "/Users/kolfert/Library/Python/3.9/lib/python/site-packages/pluggy/callers.py", line 187, in _multicall
    res = hook_impl.function(*args)
  File "/Users/kolfert/Library/Python/3.9/lib/python/site-packages/_pytest/main.py", line 334, in pytest_collection
    session.perform_collect()
  File "/Users/kolfert/Library/Python/3.9/lib/python/site-packages/_pytest/main.py", line 666, in perform_collect
    self.config.pluginmanager.check_pending()
  File "/Users/kolfert/Library/Python/3.9/lib/python/site-packages/pluggy/manager.py", line 274, in check_pending
    raise PluginValidationError(
pluggy.manager.PluginValidationError: unknown hook 'pytest_warning_captured' in plugin &lt;module 'pytest_azurepipelines' from '/Library/Frameworks/Python.framework/Versions/3.9/lib/python3.9/site-packages/pytest_azurepipelines.py'&gt;</error></testcase></testsuite></testsuites>
